<?xml version="1.0"?>
<robot xmlns:xacro="http://www.ros.org/wiki/xacro"  name="robot">

<xacro:include filename="materials.xacro" />
<xacro:include filename="inertial_macros.xacro" />


<link name="base_link">
</link>

<joint name="chassis_joint" type="fixed">
    <parent link="base_link"/>
    <child link="chassis"/>
    <origin xyz="0 0 0"/>
</joint>

<link name="chassis">


    <visual>
        <origin xyz="0.0 0 0.0" rpy="0 0 0"/>
        <geometry>
            <box size="0.188 0.15 0.03"/>
        </geometry>
        <material name="silver"/>
    </visual>

    <collision>
        <origin xyz="0.0 0 0.0" rpy="0 0 0"/>
        <geometry>
            <box size="0.188 0.15 0.03"/>
        </geometry>
        <material name="silver"/>
    </collision>

    <xacro:inertial_box mass="0.5" x="0.3" y="0.3" z="0.15">
        <origin xyz="0.15 0 0.075" rpy="0 0 0"/>
    </xacro:inertial_box>
    
</link>



<joint name="left_back_wheel_joint" type="continuous">
    <parent link="base_link"/>
    <child link="left_back_wheel"/>
    <origin xyz="-0.06 0.075 0" rpy="-${pi/2} 0 0"/>
    <axis xyz="0 0 1"/>
</joint>

<link name="left_back_wheel">
    <visual>
        <geometry>
            <cylinder length="0.025" radius="0.03" />
        </geometry>
        <material name="blue"/>
    </visual>

    <collision>
        <geometry>
            <cylinder length="0.025" radius="0.03" />
        </geometry>
        <material name="blue"/>
    </collision>

</link>


<joint name="left_front_wheel_joint" type="continuous">
    <parent link="base_link"/>
    <child link="left_front_wheel"/>
    <origin xyz="0.06 0.075 0" rpy="-${pi/2} 0 0"/>
    <axis xyz="0 0 1"/>
</joint>

<link name="left_front_wheel">
    <visual>
        <geometry>
            <cylinder length="0.025" radius="0.03" />
        </geometry>
        <material name="blue"/>
    </visual>

    <collision>
        <geometry>
            <cylinder length="0.025" radius="0.03" />
        </geometry>
        <material name="blue"/>
    </collision>

</link>


<joint name="right_front_wheel_joint" type="continuous">
    <parent link="base_link"/>
    <child link="right_front_wheel"/>
    <origin xyz="0.06 -0.075 0" rpy="${pi/2} 0 0"/>
    <axis xyz="0 0 1"/>
</joint>

<link name="right_front_wheel">
    <visual>
        <geometry>
            <cylinder length="0.025" radius="0.03" />
        </geometry>
        <material name="blue"/>
    </visual>

    <collision>
        <geometry>
            <cylinder length="0.025" radius="0.03" />
        </geometry>
        <material name="blue"/>
    </collision>
    
</link>


<joint name="right_back_wheel_joint" type="continuous">
    <parent link="base_link"/>
    <child link="right_back_wheel"/>
    <origin xyz="-0.06 -0.075 0" rpy="${pi/2} 0 0"/>
    <axis xyz="0 0 1"/>
</joint>

<link name="right_back_wheel">
    <visual>
        <geometry>
            <cylinder length="0.025" radius="0.03" />
        </geometry>
        <material name="blue"/>
    </visual>

    <collision>
        <geometry>
            <cylinder length="0.025" radius="0.03" />
        </geometry>
        <material name="blue"/>
    </collision>
    
</link>


</robot>
